<mujoco model="NaoH25V50">
    <compiler angle="radian" meshdir="./nao_meshes/meshes/V40/"/>
    <option integrator="RK4"/>
    <default>
        <joint  armature="1" damping="1"/>
    </default>
    <size njmax="500" nconmax="100" />
    <asset>
        <mesh name="RShoulderPitch_0.10" file="RShoulderPitch_0.10.stl" scale="0.1 0.1 0.1" />
        <mesh name="RShoulderRoll_0.10" file="RShoulderRoll_0.10.stl" scale="0.1 0.1 0.1" />
        <mesh name="RElbowRoll_0.10" file="RElbowRoll_0.10.stl" scale="0.1 0.1 0.1" />
        <mesh name="RWristYaw_0.10" file="RWristYaw_0.10.stl" scale="0.1 0.1 0.1" />
        <mesh name="RFinger21_0.10" file="RFinger21_0.10.stl" scale="0.1 0.1 0.1" />
        <mesh name="RFinger22_0.10" file="RFinger22_0.10.stl" scale="0.1 0.1 0.1" />
        <mesh name="RFinger23_0.10" file="RFinger23_0.10.stl" scale="0.1 0.1 0.1" />
        <mesh name="RFinger11_0.10" file="RFinger11_0.10.stl" scale="0.1 0.1 0.1" />
        <mesh name="RFinger12_0.10" file="RFinger12_0.10.stl" scale="0.1 0.1 0.1" />
        <mesh name="RFinger13_0.10" file="RFinger13_0.10.stl" scale="0.1 0.1 0.1" />
        <mesh name="RThumb1_0.10" file="RThumb1_0.10.stl" scale="0.1 0.1 0.1" />
        <mesh name="RThumb2_0.10" file="RThumb2_0.10.stl" scale="0.1 0.1 0.1" />
        <texture builtin="checker" height="100" name="texplane" rgb1="0 0 0" rgb2="0.8 0.8 0.8" type="2d" width="100"/>
        <material name="MatPlane" reflectance="0.5" shininess="1" specular="1" texrepeat="60 60" texture="texplane"/>
    </asset>

    <worldbody>
                <geom contype="1" conaffinity="1" condim="3" friction="1 .1 .1" material="MatPlane" name="floor" pos="0 0 -0.335" rgba="0.8 0.9 0.8 1" size="20 20 0.125" type="plane"/>

        
           

                <body name="RBicep" pos="0 0 0">
                    <inertial pos="0.0213201 -0.00466808 0.0004386" quat="0.527557 0.52235 0.47264 0.474811" mass="1.7996" diaginertia="0.00363268 0.00337871 0.000658873" />
                    <joint name="RShoulderRoll" pos="0 0 0" axis="0 1 0" armature="0.001" damping="5"   type="hinge"/>
                    <joint name="RShoulderPitch" pos="0 0 0" axis="0 0 1" armature="0.001" damping="5"   type="hinge"/>
                    <geom contype="2" conaffinity="1" type="mesh" rgba="0.3 0.1 0.6 1" mesh="RShoulderRoll_0.10" />
                    
                                    
                </body>
            
         
    </worldbody>
    <actuator>
        
        <motor  gear="200.0" joint="RShoulderPitch" />
        <motor  gear="200.0" joint="RShoulderRoll" />
        
    </actuator>
</mujoco>    