<mujoco model="NaoH25V50">
    <compiler angle="radian" meshdir="./nao_meshes/meshes/V40/"/>
    <option integrator="RK4"/>
    <size njmax="500" nconmax="100" />
    <asset>
        <mesh name="Torso_0.10" file="Torso_0.10.stl" scale="0.1 0.1 0.1" />
        <mesh name="HeadYaw_0.10" file="HeadYaw_0.10.stl" scale="0.1 0.1 0.1" />
        <mesh name="HeadPitch_0.10" file="HeadPitch_0.10.stl" scale="0.1 0.1 0.1" />
        <mesh name="LHipYawPitch_0.10" file="LHipYawPitch_0.10.stl" scale="0.1 0.1 0.1" />
        <mesh name="LHipRoll_0.10" file="LHipRoll_0.10.stl" scale="0.1 0.1 0.1" />
        <mesh name="LHipPitch_0.10" file="LHipPitch_0.10.stl" scale="0.1 0.1 0.1" />
        <mesh name="LKneePitch_0.10" file="LKneePitch_0.10.stl" scale="0.1 0.1 0.1" />
        <mesh name="LAnklePitch_0.10" file="LAnklePitch_0.10.stl" scale="0.1 0.1 0.1" />
        <mesh name="LAnkleRoll_0.10" file="LAnkleRoll_0.10.stl" scale="0.1 0.1 0.1" />
        <mesh name="RHipYawPitch_0.10" file="RHipYawPitch_0.10.stl" scale="0.1 0.1 0.1" />
        <mesh name="RHipRoll_0.10" file="RHipRoll_0.10.stl" scale="0.1 0.1 0.1" />
        <mesh name="RHipPitch_0.10" file="RHipPitch_0.10.stl" scale="0.1 0.1 0.1" />
        <mesh name="RKneePitch_0.10" file="RKneePitch_0.10.stl" scale="0.1 0.1 0.1" />
        <mesh name="RAnklePitch_0.10" file="RAnklePitch_0.10.stl" scale="0.1 0.1 0.1" />
        <mesh name="RAnkleRoll_0.10" file="RAnkleRoll_0.10.stl" scale="0.1 0.1 0.1" />
        <mesh name="LShoulderPitch_0.10" file="LShoulderPitch_0.10.stl" scale="0.1 0.1 0.1" />
        <mesh name="LShoulderRoll_0.10" file="LShoulderRoll_0.10.stl" scale="0.1 0.1 0.1" />
        <mesh name="LElbowRoll_0.10" file="LElbowRoll_0.10.stl" scale="0.1 0.1 0.1" />
        <mesh name="LWristYaw_0.10" file="LWristYaw_0.10.stl" scale="0.1 0.1 0.1" />
        <mesh name="LFinger21_0.10" file="LFinger21_0.10.stl" scale="0.1 0.1 0.1" />
        <mesh name="LFinger22_0.10" file="LFinger22_0.10.stl" scale="0.1 0.1 0.1" />
        <mesh name="LFinger23_0.10" file="LFinger23_0.10.stl" scale="0.1 0.1 0.1" />
        <mesh name="LFinger11_0.10" file="LFinger11_0.10.stl" scale="0.1 0.1 0.1" />
        <mesh name="LFinger12_0.10" file="LFinger12_0.10.stl" scale="0.1 0.1 0.1" />
        <mesh name="LFinger13_0.10" file="LFinger13_0.10.stl" scale="0.1 0.1 0.1" />
        <mesh name="LThumb1_0.10" file="LThumb1_0.10.stl" scale="0.1 0.1 0.1" />
        <mesh name="LThumb2_0.10" file="LThumb2_0.10.stl" scale="0.1 0.1 0.1" />
        <mesh name="RShoulderPitch_0.10" file="RShoulderPitch_0.10.stl" scale="0.1 0.1 0.1" />
        <mesh name="RShoulderRoll_0.10" file="RShoulderRoll_0.10.stl" scale="0.1 0.1 0.1" />
        <mesh name="RElbowRoll_0.10" file="RElbowRoll_0.10.stl" scale="0.1 0.1 0.1" />
        <mesh name="RWristYaw_0.10" file="RWristYaw_0.10.stl" scale="0.1 0.1 0.1" />
        <mesh name="RFinger21_0.10" file="RFinger21_0.10.stl" scale="0.1 0.1 0.1" />
        <mesh name="RFinger22_0.10" file="RFinger22_0.10.stl" scale="0.1 0.1 0.1" />
        <mesh name="RFinger23_0.10" file="RFinger23_0.10.stl" scale="0.1 0.1 0.1" />
        <mesh name="RFinger11_0.10" file="RFinger11_0.10.stl" scale="0.1 0.1 0.1" />
        <mesh name="RFinger12_0.10" file="RFinger12_0.10.stl" scale="0.1 0.1 0.1" />
        <mesh name="RFinger13_0.10" file="RFinger13_0.10.stl" scale="0.1 0.1 0.1" />
        <mesh name="RThumb1_0.10" file="RThumb1_0.10.stl" scale="0.1 0.1 0.1" />
        <mesh name="RThumb2_0.10" file="RThumb2_0.10.stl" scale="0.1 0.1 0.1" />
        <texture builtin="checker" height="100" name="texplane" rgb1="0 0 0" rgb2="0.8 0.8 0.8" type="2d" width="100"/>
        <material name="MatPlane" reflectance="0.5" shininess="1" specular="1" texrepeat="60 60" texture="texplane"/>
    </asset>
    <worldbody>
        <geom contype="1" conaffinity="0" condim="3" friction="1 .1 .1" material="MatPlane" name="floor" pos="0 0 -0.335" rgba="0.8 0.9 0.8 1" size="20 20 0.125" type="plane"/>
        <body name="torso" pos="0 0 0" >
            <inertial pos="0.00370371 -4.6229e-05 0.0443536" quat="0.999942 -6.0823e-05 -0.0105352 0.00208575" mass="9.12902" diaginertia="0.0307424 0.0269618 0.0139481" />
        	<joint type="free"/>
            <geom contype="2" conaffinity="1" type="mesh" rgba="0.3 0.1 0.5 1" mesh="Torso_0.10" name="torso"
                />
            <body name="Neck" pos="0 0 0.1265" >
                <inertial pos="8.30672e-09 -1.22139e-08 0.000122854" quat="0 0.707107 0 0.707107" mass="0.090746" diaginertia="1.15255e-05 8.6441e-06 8.6441e-06" />
                <joint name="HeadYaw" pos="0 0 0" axis="0 0 1" limited="true" range="-2.08567 2.08567" />
                <geom contype="4" conaffinity="1" type="mesh" rgba="0.5 1 0.5 1" mesh="HeadYaw_0.10" />
                <body name="Head" pos="0 0 0">
                    <inertial pos="-0.000379894 -4.82308e-05 0.0560861" quat="0.562244 0.562237 -0.42882 0.428818" mass="5.25935" diaginertia="0.0088094 0.00839445 0.00702492" />
                    <joint name="HeadPitch" pos="0 0 0" axis="0 1 0" limited="true" range="-0.671952 0.514872" />
                    <geom contype="4" conaffinity="1" type="mesh" rgba="1 0.3 0.5 1" mesh="HeadPitch_0.10" />
                    <body name="gaze" pos="0.05871 0 0.06364">
                        <inertial pos="0.05871 0 0.06364" mass="0" diaginertia="0 0 0" />
                    </body>
                    <body name="HeadTouchFront_frame" pos="0.0312 0 0.1014" quat="0.82924 0 -0.558893 0">
                        <inertial pos="0.0312 0 0.1014" quat="0.82924 0 -0.558893 0" mass="0" diaginertia="0 0 0" />
                    </body>
                    <body name="CameraBottom_frame" pos="0.05071 0 0.01774" quat="0.940585 0 0.339559 0">
                        <inertial pos="0.05071 0 0.01774" quat="0.940585 0 0.339559 0" mass="0" diaginertia="0 0 0" />
                        <body name="CameraBottom_optical_frame" pos="0 0 0" quat="0.5 -0.5 0.5 -0.5">
                            <inertial pos="0 0 0" quat="0.5 -0.5 0.5 -0.5" mass="0" diaginertia="0 0 0" />
                        </body>
                    </body>
                    <body name="CameraTop_frame" pos="0.05871 0 0.06364" quat="0.999945 0 0.0104716 0">
                        <inertial pos="0.05871 0 0.06364" quat="0.999945 0 0.0104716 0" mass="0" diaginertia="0 0 0" />
                        <body name="CameraTop_optical_frame" pos="0 0 0" quat="0.5 -0.5 0.5 -0.5">
                            <inertial pos="0 0 0" quat="0.5 -0.5 0.5 -0.5" mass="0" diaginertia="0 0 0" />
                        </body>
                    </body>
                    <body name="LInfraRed_frame" pos="0.0441 0.0257 0.0466">
                        <inertial pos="0.0441 0.0257 0.0466" mass="0" diaginertia="0 0 0" />
                    </body>
                    <body name="HeadTouchRear_frame" pos="-0.0257 0 0.1045" quat="0.618313 2.22395e-07 -0.785932 -2.22395e-07">
                        <inertial pos="-0.0257 0 0.1045" quat="0.618313 2.22395e-07 -0.785932 -2.22395e-07" mass="0" diaginertia="0 0 0" />
                    </body>
                    <body name="HeadTouchMiddle_frame" pos="0.001 0 0.1099" quat="0.707105 5.93571e-12 -0.707109 -5.93571e-12">
                        <inertial pos="0.001 0 0.1099" quat="0.707105 5.93571e-12 -0.707109 -5.93571e-12" mass="0" diaginertia="0 0 0" />
                    </body>
                    <body name="RInfraRed_frame" pos="0.0441 -0.0257 0.0466">
                        <inertial pos="0.0441 -0.0257 0.0466" mass="0" diaginertia="0 0 0" />
                    </body>
                </body>
            </body>
            <body name="LPelvis" pos="0 0.05 -0.085">
                <inertial pos="-0.0128803 -0.00708774 0.0134709" quat="0.433195 0.551012 0.2317 0.674568" mass="0.611599" diaginertia="0.000387067 0.000291373 0.000173947" />
                <joint name="LHipYawPitch" pos="0 0 0" axis="0 0.707107 -0.707107" limited="true" range="-1.14529 0.740718" />
                <geom contype="8" conaffinity="5" type="mesh" rgba="1 0.423529 0.0392157 1" mesh="LHipYawPitch_0.10" />
                <body name="LHip" pos="0 0 0">
                    <inertial pos="-0.0169128 -0.000488904 -0.00699163" quat="0.501404 0.490618 0.512214 0.495505" mass="0.209205" diaginertia="7.40981e-05 6.66862e-05 2.17666e-05" />
                    <joint name="LHipRoll" pos="0 0 0" axis="1 0 0" limited="true" range="-0.379435 0.79046" />
                    <geom contype="8" conaffinity="5" type="mesh" rgba="1 0.423529 0.0392157 1" mesh="LHipRoll_0.10" />
                    <body name="LThigh" pos="0 0 0">
                        <inertial pos="0.00162372 0.00149476 -0.0518995" quat="0.993119 -0.00358341 -0.117056 0.000122069" mass="2.95157" diaginertia="0.00455217 0.00411878 0.00210523" />
                        <joint name="LHipPitch" pos="0 0 0" axis="0 1 0" limited="true" range="-1.53589 0.48398" />
                        <geom contype="8" conaffinity="5" type="mesh" rgba="1 0.3 0.5 1" mesh="LHipPitch_0.10" />
                        <body name="LTibia" pos="0 0 -0.1">
                            <inertial pos="0.00330151 0.00251579 -0.0628225" quat="0.996053 0.0189271 0.0852725 0.0157606" mass="2.28319" diaginertia="0.00337036 0.00289491 0.00133895" />
                            <joint name="LKneePitch" pos="0 0 0" axis="0 1 0" limited="true" range="-0.0923279 2.11255" />
                            <geom contype="16" conaffinity="15" type="mesh" rgba="0.8 0.4 0.9 1" mesh="LKneePitch_0.10" />
                            <body name="LAnklePitch" pos="0 0 -0.1029">
                                <inertial pos="8.6838e-05 0.000306029 0.0100665" quat="0.46591 0.527213 0.543286 0.458055" mass="0.412051" diaginertia="0.000179707 0.00013171 9.56695e-05" />
                                <joint name="LAnklePitch" pos="0 0 0" axis="0 1 0" limited="true" range="-1.18944 0.922581" />
                                <geom contype="16" conaffinity="15" type="mesh" rgba="0.5 0.7 1 1" mesh="LAnklePitch_0.10" />
                                <body name="l_ankle" pos="0 0 0">
                                    <inertial pos="0.0221765 0.00251761 -0.0253037" quat="0.0468406 0.747433 0.0373057 0.661633" mass="2.46597" diaginertia="0.00538819 0.00501931 0.0011678" />
                                    <joint name="LAnkleRoll" pos="0 0 0" axis="1 0 0" limited="true" range="-0.397761 0.768992" />
                                    <geom contype="16" conaffinity="15" type="mesh" rgba="0.5 0.7 1 1" mesh="LAnkleRoll_0.10" />
                                    <body name="l_sole" pos="0 0 -0.04511">
                                        <inertial pos="0 0 -0.04511" mass="0" diaginertia="0 0 0" />
                                    </body>
                                    <body name="LFootBumperRight_frame" pos="0.0876 -0.014 -0.0353">
                                        <inertial pos="0.0876 -0.014 -0.0353" mass="0" diaginertia="0 0 0" />
                                    </body>
                                    <body name="LFsrFR_frame" pos="0.07025 -0.0231 -0.04511">
                                        <inertial pos="0 0 0" mass="0.00305027" diaginertia="3.17737e-08 3.17737e-08 5.08379e-08" />
                                        <geom contype="16" conaffinity="15" size="0.005 0.005 0.0025" type="box" />
                                    </body>
                                    <body name="LFsrRR_frame" pos="-0.02965 -0.0191 -0.04511">
                                        <inertial pos="0 0 0" mass="0.00305027" diaginertia="3.17737e-08 3.17737e-08 5.08379e-08" />
                                        <geom contype="16" conaffinity="15" size="0.005 0.005 0.0025" type="box" />
                                    </body>
                                    <body name="LFsrFL_frame" pos="0.07025 0.0299 -0.04511">
                                        <inertial pos="0 0 0" mass="0.00305027" diaginertia="3.17737e-08 3.17737e-08 5.08379e-08" />
                                        <geom contype="16" conaffinity="15" size="0.005 0.005 0.0025" type="box" />
                                    </body>
                                    <body name="LFsrRL_frame" pos="-0.03025 0.0299 -0.04511">
                                        <inertial pos="0 0 0" mass="0.00305027" diaginertia="3.17737e-08 3.17737e-08 5.08379e-08" />
                                        <geom contype="16" conaffinity="15" size="0.005 0.005 0.0025" type="box" />
                                    </body>
                                    <body name="LFootBumperLeft_frame" pos="0.0876 0.019 -0.0353">
                                        <inertial pos="0.0876 0.019 -0.0353" mass="0" diaginertia="0 0 0" />
                                    </body>
                                </body>
                            </body>
                        </body>
                    </body>
                </body>
            </body>
            <body name="RPelvis" pos="0 -0.05 -0.085">
                <inertial pos="-0.012943 0.00725106 0.0138017" quat="0.677718 0.226723 0.550219 0.431919" mass="0.599907" diaginertia="0.000377649 0.000285519 0.000167268" />
                <joint name="RHipYawPitch" pos="0 0 0" axis="0 0.707107 0.707107" limited="true" range="-1.14529 0.740718" />
                <geom contype="32" conaffinity="29" type="mesh" rgba="0.3 0.1 0.6 1" mesh="RHipYawPitch_0.10" />
                <body name="RHip" pos="0 0 0">
                    <inertial pos="-0.0169298 -0.00139763 -0.00698282" quat="0.510087 0.484407 0.518022 0.486636" mass="0.208296" diaginertia="7.38725e-05 6.63941e-05 2.16102e-05" />
                    <joint name="RHipRoll" pos="0 0 0" axis="1 0 0" limited="true" range="-0.79046 0.379435" />
                    <geom contype="32" conaffinity="29" type="mesh" rgba="0.3 0.1 0.6 1" mesh="RHipRoll_0.10" />
                    <body name="RThigh" pos="0 0 0">
                        <inertial pos="0.00182967 -0.00149209 -0.0523413" quat="0.993317 0.0125884 -0.11457 -0.00598517" mass="2.93957" diaginertia="0.00448244 0.00405421 0.00210433" />
                        <joint name="RHipPitch" pos="0 0 0" axis="0 1 0" limited="true" range="-1.53589 0.48398" />
                        <geom contype="32" conaffinity="29" type="mesh" rgba="0.8 0.2 1 1" mesh="RHipPitch_0.10" />
                        <body name="RTibia" pos="0 0 -0.1">
                            <inertial pos="0.00319121 -0.00240692 -0.0633783" quat="0.996198 -0.0186793 0.0844245 -0.0106731" mass="2.27994" diaginertia="0.00335227 0.00285703 0.00134993" />
                            <joint name="RKneePitch" pos="0 0 0" axis="0 1 0" limited="true" range="-0.0923279 2.11255" />
                            <geom contype="64" conaffinity="63" type="mesh" rgba="0.8 0.2 1 1" mesh="RKneePitch_0.10" />
                            <body name="RAnklePitch" pos="0 0 -0.1029">
                                <inertial pos="0.00232181 -4.79787e-05 0.0171042" quat="0.461248 0.533738 0.597083 0.381924" mass="0.374293" diaginertia="0.000159198 0.000120062 7.79115e-05" />
                                <joint name="RAnklePitch" pos="0 0 0" axis="0 1 0" limited="true" range="-1.1863 0.932006" />
                                <geom contype="64" conaffinity="63" type="mesh" rgba="0.1 0.4 0.6 1" mesh="RAnklePitch_0.10" />
                                <body name="r_ankle" pos="0 0 0">
                                    <inertial pos="0.0229928 -0.00257944 -0.0257303" quat="-0.0427709 0.745477 -0.0318629 0.664394" mass="2.47737" diaginertia="0.00546571 0.00507821 0.00117884" />
                                    <joint name="RAnkleRoll" pos="0 0 0" axis="1 0 0" limited="true" range="-0.768992 0.397761" />
                                    <geom contype="64" conaffinity="63" type="mesh" rgba="0.1 0.4 0.6 1" mesh="RAnkleRoll_0.10" />
                                    <body name="r_sole" pos="0 0 -0.04511">
                                        <inertial pos="0 0 -0.04511" mass="0" diaginertia="0 0 0" />
                                    </body>
                                    <body name="RFsrRL_frame" pos="-0.03025 0.0191 -0.04511">
                                        <inertial pos="0 0 0" mass="0.00305027" diaginertia="3.17737e-08 3.17737e-08 5.08379e-08" />
                                        <geom contype="64" conaffinity="63" size="0.005 0.005 0.0025" type="box" />
                                    </body>
                                    <body name="RFsrRR_frame" pos="-0.02965 -0.0299 -0.04511">
                                        <inertial pos="0 0 0" mass="0.00305027" diaginertia="3.17737e-08 3.17737e-08 5.08379e-08" />
                                        <geom contype="64" conaffinity="63" size="0.005 0.005 0.0025" type="box" />
                                    </body>
                                    <body name="RFootBumperRight_frame" pos="0.0876 -0.019 -0.0353">
                                        <inertial pos="0.0876 -0.019 -0.0353" mass="0" diaginertia="0 0 0" />
                                    </body>
                                    <body name="RFsrFR_frame" pos="0.07025 -0.0299 -0.04511">
                                        <inertial pos="0 0 0" mass="0.00305027" diaginertia="3.17737e-08 3.17737e-08 5.08379e-08" />
                                        <geom contype="64" conaffinity="63" size="0.005 0.005 0.0025" type="box" />
                                    </body>
                                    <body name="RFootBumperLeft_frame" pos="0.0876 0.014 -0.0353">
                                        <inertial pos="0.0876 0.014 -0.0353" mass="0" diaginertia="0 0 0" />
                                    </body>
                                    <body name="RFsrFL_frame" pos="0.07025 0.0231 -0.04511">
                                        <inertial pos="0 0 0" mass="0.00305027" diaginertia="3.17737e-08 3.17737e-08 5.08379e-08" />
                                        <geom contype="64" conaffinity="63" size="0.005 0.005 0.0025" type="box" />
                                    </body>
                                </body>
                            </body>
                        </body>
                    </body>
                </body>
            </body>
            <body name="LShoulder" pos="0 0.098 0.1" quat="1 0 0 0">
                <inertial pos="-0.0147798 -0.0177741 -0.000761746" quat="0.786467 0.0218088 -0.018285 -0.616976" mass="0.182847" diaginertia="7.30177e-05 5.28928e-05 2.56637e-05" />
                <joint name="LShoulderPitch" pos="0 0 0" axis="0 1 0" limited="true" range="-2.08567 2.08567" />
                <geom contype="128" conaffinity="125" type="mesh" rgba="0.8 0.2 0.8 1" mesh="LShoulderPitch_0.10" />
                <body name="LBicep" pos="0 0 0">
                    <inertial pos="0.0212509 0.00488998 0.000310127" quat="0.466845 0.469092 0.526354 0.533817" mass="1.79641" diaginertia="0.00363826 0.00338653 0.00065475" />
                    <joint name="LShoulderRoll" pos="0 0 0" axis="0 0 1" limited="true" range="-0.314159 1.32645" />
                    <geom contype="128" conaffinity="125" type="mesh" rgba="0.2 0.5 0.5 1" mesh="LShoulderRoll_0.10" />
                    <body name="LElbow" pos="0.105 0.015 0">
                        <inertial pos="-0.02744 0 -0.00014" quat="-0.000545392 0.711779 -0.000696018 0.702403" mass="0.395499" diaginertia="0.000168578 0.000162384 3.41143e-05" />
                        <joint name="LElbowYaw" pos="0 0 0" axis="1 0 0" limited="true" range="-2.08567 2.08567" />
                        <body name="LForeArm" pos="0 0 0">
                            <inertial pos="0.0217609 0.00292434 0.00220744" quat="0.509877 0.677216 0.322959 0.420835" mass="0.438641" diaginertia="0.000165863 0.00014172 0.00010203" />
                            <joint name="LElbowRoll" pos="0 0 0" axis="0 0 1" limited="true" range="-1.54462 -0.0349066" />
                            <geom contype="256" conaffinity="127" type="mesh" rgba="0.5 1 0.5 1" mesh="LElbowRoll_0.10" />
                            <body name="l_wrist" pos="0.05595 0 0">
                                <inertial pos="0.0440184 -2.52556e-05 0.00469772" quat="0.00671586 0.513524 0.00738942 0.858017" mass="0.952048" diaginertia="0.000589689 0.000528019 0.000364717" />
                                <joint name="LWristYaw" pos="0 0 0" axis="1 0 0" limited="true" range="-1.82387 1.82387" />
                                <geom contype="256" conaffinity="255" type="mesh" rgba="1 0.3 0.5 1" mesh="LWristYaw_0.10" />
                                <body name="l_gripper" pos="0.05775 0 -0.01231">
                                    <inertial pos="0 0 0" mass="1.22011e-05" diaginertia="6.7106e-09 6.7106e-09 6.7106e-09" />
                                    <joint name="LHand" pos="0 0 0" axis="1 0 0" limited="true" range="0 1" />
                                </body>
                                <body name="LHandTouchLeft_frame" pos="0.032 0.025 0.003" quat="0.707105 0 0 0.707108">
                                    <inertial pos="0.032 0.025 0.003" quat="0.707105 0 0 0.707108" mass="0" diaginertia="0 0 0" />
                                </body>
                                <body name="LHandTouchBack_frame" pos="0.038 0 0.025" quat="-0.707108 1.87637e-06 0.707105 1.87637e-06">
                                    <inertial pos="0.038 0 0.025" quat="-0.707108 1.87637e-06 0.707105 1.87637e-06" mass="0" diaginertia="0 0 0" />
                                </body>
                                <body name="LHandTouchRight_frame" pos="0.035 -0.025 0.0035" quat="0.707105 0 0 -0.707108">
                                    <inertial pos="0.035 -0.025 0.0035" quat="0.707105 0 0 -0.707108" mass="0" diaginertia="0 0 0" />
                                </body>
                                <body name="LFinger21_link" pos="0.06907 -0.01157 -0.00304" quat="0.672286 0.564114 0.308141 -0.367227">
                                    <inertial pos="0.00881001 -3.5261e-07 0.000460066" quat="0.0927872 0.633796 0.0284959 0.767386" mass="0.00932716" diaginertia="2.89089e-07 2.07231e-07 1.87427e-07" />
                                    <joint name="LFinger21" pos="0 0 0" axis="0 0 1" />
                                    <geom contype="256" conaffinity="255" type="mesh" rgba="0.1 0.1 0.1 0.4" mesh="LFinger21_0.10" />
                                    <body name="LFinger22_link" pos="0.01436 0 0" quat="0.877607 0 0 -0.479381">
                                        <inertial pos="0.00854485 -9.9436e-05 0.000483262" quat="0.11741 0.630555 0.00225006 0.767209" mass="0.0093255" diaginertia="2.89287e-07 2.07724e-07 1.86943e-07" />
                                        <joint name="LFinger22" pos="0 0 0" axis="0 0 1" />
                                        <geom contype="256" conaffinity="255" type="mesh" rgba="0.1 0.1 0.1 0.4" mesh="LFinger22_0.10" />
                                        <body name="LFinger23_link" pos="0.01436 0 0" quat="0.877607 0 0 -0.479381">
                                            <inertial pos="0.00860938 -0.000273406 0.000175458" quat="0.0467005 0.710615 0.0483532 0.700363" mass="0.0090357" diaginertia="2.82977e-07 2.15498e-07 1.64221e-07" />
                                            <joint name="LFinger23" pos="0 0 0" axis="0 0 1" />
                                            <geom contype="256" conaffinity="255" type="mesh" rgba="0.1 0.1 0.1 0.4" mesh="LFinger23_0.10" />
                                        </body>
                                    </body>
                                </body>
                                <body name="LFinger11_link" pos="0.06907 0.01157 -0.00304" quat="0.564115 0.672285 0.367228 -0.30814">
                                    <inertial pos="0.00853596 -0.000339914 0.000170124" quat="0.00656248 0.640359 -0.133049 0.756436" mass="0.00934584" diaginertia="2.89949e-07 2.08267e-07 1.87716e-07" />
                                    <joint name="LFinger11" pos="0 0 0" axis="0 0 1" />
                                    <geom contype="256" conaffinity="255" type="mesh" rgba="0.1 0.1 0.1 0.4" mesh="LFinger11_0.10" />
                                    <body name="LFinger12_link" pos="0.01436 0 0" quat="0.877607 0 0 -0.479381">
                                        <inertial pos="0.00851477 -0.000540798 0.000316328" quat="0.00479288 0.641516 -0.129224 0.756132" mass="0.00931936" diaginertia="2.89039e-07 2.07549e-07 1.86708e-07" />
                                        <joint name="LFinger12" pos="0 0 0" axis="0 0 1" />
                                        <geom contype="256" conaffinity="255" type="mesh" rgba="0.1 0.1 0.1 0.4" mesh="LFinger12_0.10" />
                                        <body name="LFinger13_link" pos="0.01436 0 0" quat="0.877607 0 0 -0.479381">
                                            <inertial pos="0.00848591 -0.000538296 -0.000114859" quat="-0.0767885 0.70615 -0.0816382 0.699136" mass="0.00901582" diaginertia="2.82009e-07 2.12832e-07 1.65102e-07" />
                                            <joint name="LFinger13" pos="0 0 0" axis="0 0 1" />
                                            <geom contype="256" conaffinity="255" type="mesh" rgba="0.1 0.1 0.1 0.4" mesh="LFinger13_0.10" />
                                        </body>
                                    </body>
                                </body>
                                <body name="LThumb1_link" pos="0.04895 0 -0.02638" quat="0.706908 -0.70691 0.0167209 0.016721">
                                    <inertial pos="0.00497911 0.000265815 -0.00591955" quat="0.988554 0.0920316 -0.118432 0.0162819" mass="0.00932644" diaginertia="2.8785e-07 2.06916e-07 1.87364e-07" />
                                    <joint name="LThumb1" pos="0 0 0" axis="0 0 1" />
                                    <geom contype="256" conaffinity="255" type="mesh" rgba="0.1 0.1 0.1 0.4" mesh="LThumb1_0.10" />
                                    <body name="LThumb2_link" pos="0.01436 0 0" quat="0.877607 0 0 -0.479381">
                                        <inertial pos="0.00259174 6.32101e-05 -0.00888251" quat="0.963351 0.000866356 -0.267959 -0.0122959" mass="0.00906337" diaginertia="2.83912e-07 2.16711e-07 1.64842e-07" />
                                        <joint name="LThumb2" pos="0 0 0" axis="0 0 1" />
                                        <geom contype="256" conaffinity="255" type="mesh" rgba="0.1 0.1 0.1 0.4" mesh="LThumb2_0.10" />
                                    </body>
                                </body>
                            </body>
                        </body>
                    </body>
                </body>
            </body>
            <body name="RShoulder" pos="0 -0.098 0.1" quat="1 0 0 0">
                <inertial pos="-0.0146753 0.0178377 0.000381054" quat="0.611486 -0.00891285 -0.0112889 0.791124" mass="0.183785" diaginertia="7.45353e-05 5.40081e-05 2.59944e-05" />
                <joint name="RShoulderPitch" pos="0 0 0" axis="0 1 0" limited="true" range="-2.08567 2.08567" />
                <geom contype="512" conaffinity="509" type="mesh" rgba="0.8 0.4 0.9 1" mesh="RShoulderPitch_0.10" />
                <body name="RBicep" pos="0 0 0">
                    <inertial pos="0.0213201 -0.00466808 0.0004386" quat="0.527557 0.52235 0.47264 0.474811" mass="1.7996" diaginertia="0.00363268 0.00337871 0.000658873" />
                    <joint name="RShoulderRoll" pos="0 0 0" axis="0 0 1" limited="true" range="-1.32645 0.314159" />
                    <geom contype="512" conaffinity="509" type="mesh" rgba="0.3 0.1 0.6 1" mesh="RShoulderRoll_0.10" />
                    <body name="RElbow" pos="0.105 -0.015 0">
                        <inertial pos="-0.02744 0 -0.00014" quat="-0.000545392 0.711779 -0.000696018 0.702403" mass="0.395499" diaginertia="0.000168578 0.000162384 3.41143e-05" />
                        <joint name="RElbowYaw" pos="0 0 0" axis="1 0 0" limited="true" range="-2.08567 2.08567" />
                        <body name="RForeArm" pos="0 0 0">
                            <inertial pos="0.0235942 -0.00369779 0.00274973" quat="0.397369 0.35311 0.66416 0.525645" mass="0.455913" diaginertia="0.000171173 0.000151629 0.000108766" />
                            <joint name="RElbowRoll" pos="0 0 0" axis="0 0 1" limited="true" range="0.0349066 1.54462" />
                            <geom contype="1024" conaffinity="511" type="mesh" rgba="0.8 0.2 1 1" mesh="RElbowRoll_0.10" />
                            <body name="r_wrist" pos="0.05595 0 0">
                                <inertial pos="0.0432841 -3.00946e-05 0.00454347" quat="0.0130028 0.518963 0.00333335 0.854691" mass="0.93576" diaginertia="0.000578664 0.000517583 0.000351545" />
                                <joint name="RWristYaw" pos="0 0 0" axis="1 0 0" limited="true" range="-1.82387 1.82387" />
                                <geom contype="1024" conaffinity="1023" type="mesh" rgba="0.1 0.4 0.6 1" mesh="RWristYaw_0.10" />
                                <body name="r_gripper" pos="0.05775 0 -0.01213">
                                    <inertial pos="0 0 0" mass="1.22011e-05" diaginertia="6.7106e-09 6.7106e-09 6.7106e-09" />
                                    <joint name="RHand" pos="0 0 0" axis="1 0 0" limited="true" range="0 1" />
                                </body>
                                <body name="RHandTouchRight_frame" pos="0.035 -0.025 0.0035" quat="0.707105 0 0 -0.707108">
                                    <inertial pos="0.035 -0.025 0.0035" quat="0.707105 0 0 -0.707108" mass="0" diaginertia="0 0 0" />
                                </body>
                                <body name="RHandTouchBack_frame" pos="0.038 0 0.025" quat="-0.707108 1.87637e-06 0.707105 1.87637e-06">
                                    <inertial pos="0.038 0 0.025" quat="-0.707108 1.87637e-06 0.707105 1.87637e-06" mass="0" diaginertia="0 0 0" />
                                </body>
                                <body name="RHandTouchLeft_frame" pos="0.032 0.025 0.003" quat="0.707105 0 0 0.707108">
                                    <inertial pos="0.032 0.025 0.003" quat="0.707105 0 0 0.707108" mass="0" diaginertia="0 0 0" />
                                </body>
                                <body name="RFinger21_link" pos="0.06907 -0.01157 -0.00304" quat="0.672286 0.564114 0.308141 -0.367227">
                                    <inertial pos="0.00863736 0.000185977 1.64388e-05" quat="-0.0910756 0.633824 -0.0291972 0.767541" mass="0.0093394" diaginertia="2.89187e-07 2.07156e-07 1.88181e-07" />
                                    <joint name="RFinger21" pos="0 0 0" axis="0 0 1" />
                                    <geom contype="1024" conaffinity="1023" type="mesh" rgba="0.1 0.1 0.1 0.4" mesh="RFinger21_0.10" />
                                    <body name="RFinger22_link" pos="0.01436 0 0" quat="0.877607 0 0 -0.479381">
                                        <inertial pos="0.00844989 -0.000471502 0.000379654" quat="-0.11611 0.630939 -0.00405049 0.767084" mass="0.00931936" diaginertia="2.89039e-07 2.07549e-07 1.86708e-07" />
                                        <joint name="RFinger22" pos="0 0 0" axis="0 0 1" />
                                        <geom contype="1024" conaffinity="1023" type="mesh" rgba="0.1 0.1 0.1 0.4" mesh="RFinger22_0.10" />
                                        <body name="RFinger23_link" pos="0.01436 0 0" quat="0.877607 0 0 -0.479381">
                                            <inertial pos="0.00854807 -0.000314659 0.00014057" quat="-0.0663958 0.707447 -0.0375616 0.702638" mass="0.00911458" diaginertia="2.88584e-07 2.20008e-07 1.65953e-07" />
                                            <joint name="RFinger23" pos="0 0 0" axis="0 0 1" />
                                            <geom contype="1024" conaffinity="1023" type="mesh" rgba="0.1 0.1 0.1 0.4" mesh="RFinger23_0.10" />
                                        </body>
                                    </body>
                                </body>
                                <body name="RFinger11_link" pos="0.06907 0.01157 -0.00304" quat="0.564115 0.672285 0.367228 -0.30814">
                                    <inertial pos="0.00903321 -0.000223157 0.000206259" quat="0.00825309 0.642265 0.118529 0.757217" mass="0.00926401" diaginertia="2.85933e-07 2.0779e-07 1.82763e-07" />
                                    <joint name="RFinger11" pos="0 0 0" axis="0 0 1" />
                                    <geom contype="1024" conaffinity="1023" type="mesh" rgba="0.1 0.1 0.1 0.4" mesh="RFinger11_0.10" />
                                    <body name="RFinger12_link" pos="0.01436 0 0" quat="0.877607 0 0 -0.479381">
                                        <inertial pos="0.00740736 -4.2145e-05 3.50086e-05" quat="0.018982 0.639915 0.106374 0.760811" mass="0.00934554" diaginertia="2.89434e-07 2.07315e-07 1.88431e-07" />
                                        <joint name="RFinger12" pos="0 0 0" axis="0 0 1" />
                                        <geom contype="1024" conaffinity="1023" type="mesh" rgba="0.1 0.1 0.1 0.4" mesh="RFinger12_0.10" />
                                        <body name="RFinger13_link" pos="0.01436 0 0" quat="0.877607 0 0 -0.479381">
                                            <inertial pos="0.00824432 3.0634e-05 -9.09988e-05" quat="0.0769785 0.705516 0.0821836 0.699691" mass="0.00899706" diaginertia="2.80311e-07 2.13423e-07 1.63303e-07" />
                                            <joint name="RFinger13" pos="0 0 0" axis="0 0 1" />
                                            <geom contype="1024" conaffinity="1023" type="mesh" rgba="0.1 0.1 0.1 0.4" mesh="RFinger13_0.10" />
                                        </body>
                                    </body>
                                </body>
                                <body name="RThumb1_link" pos="0.04895 0 -0.02638" quat="0.706908 -0.70691 0.0167209 0.016721">
                                    <inertial pos="0.00605392 5.45792e-05 -0.00555008" quat="0.988351 -0.0944312 -0.118218 -0.0164253" mass="0.00933258" diaginertia="2.88099e-07 2.07093e-07 1.87599e-07" />
                                    <joint name="RThumb1" pos="0 0 0" axis="0 0 1" />
                                    <geom contype="1024" conaffinity="1023" type="mesh" rgba="0.1 0.1 0.1 0.4" mesh="RThumb1_0.10" />
                                    <body name="RThumb2_link" pos="0.01436 0 0" quat="0.877607 0 0 -0.479381">
                                        <inertial pos="0.00294165 -0.000445346 -0.00797671" quat="0.962667 0.0074404 -0.270146 0.0154311" mass="0.00904133" diaginertia="2.84681e-07 2.16067e-07 1.64498e-07" />
                                        <joint name="RThumb2" pos="0 0 0" axis="0 0 1" />
                                        <geom contype="1024" conaffinity="1023" type="mesh" rgba="0.1 0.1 0.1 0.4" mesh="RThumb2_0.10" />
                                    </body>
                                </body>
                				<site name="reacher" pos="0.075 0 -0.001" size="0.01 0.01 0.01" rgba="1 1 1 1"></site>
                            </body>
                        </body>
                    </body>
                </body>
            </body>
            <body name="ImuTorsoAccelerometer_frame" pos="-0.008 0.00606 0.027">
                <inertial pos="-0.008 0.00606 0.027" mass="0" diaginertia="0 0 0" />
            </body>
            <body name="RSonar_frame" pos="0.00558253 -0.0192068 0.0623853" quat="0.980564 0.00660077 0.0209379 -0.194968">
                <inertial pos="0.00558253 -0.0192068 0.0623853" quat="0.980564 0.00660077 0.0209379 -0.194968" mass="0" diaginertia="0 0 0" />
            </body>
            <body name="LSonar_frame" pos="0.00558253 0.0192068 0.0623853" quat="0.980564 -0.00660077 0.0209379 0.194968">
                <inertial pos="0.00558253 0.0192068 0.0623853" quat="0.980564 -0.00660077 0.0209379 0.194968" mass="0" diaginertia="0 0 0" />
            </body>
            <body name="ImuTorsoGyrometer_frame" pos="-0.008 0.006 0.029">
                <inertial pos="-0.008 0.006 0.029" mass="0" diaginertia="0 0 0" />
            </body>
            <body name="ChestButton_frame" pos="0.049871 0.001588 0.055163">
                <inertial pos="0.049871 0.001588 0.055163" mass="0" diaginertia="0 0 0" />
            </body>
        </body>
        <site name="target" pos="0.125 0.125 0.125" size="0.01 0.01 0.01" rgba="1 0 0 1"></site>
    </worldbody>
</mujoco>
